Workbook

Sheet Readme
A1: eToro copy-trading suitability test
B3: What this is | C3: A working model of the live suitability formula that gates copy trading and Smart Portfolios at eToro. Scoring is taken verbatim from the live ClientRiskProfileConfiguration documents CySEC-24, FCA-15, ASIC-9, ASIC GAML-15 and FSRA-10, read from the production Cosmos account.
B5: Sheets
B6: One tab per regulation | C6: Pick the tab for the regulation the user falls under - CySEC v24, FCA v15, ASIC v9, ASIC GAML v15, FSRA v10. Answer the yellow cells and you get a risk profile and a maximum copyable risk score. Covers gate 1 (hard block) and gate 2 (risk-score cap). Each tab shows only the questions and block conditions that regulation actually uses, so nothing on screen is inapplicable.
B7: Monitoring | C7: Gate 3, the daily solvency check. Blocks new copies when copy utilisation exceeds financial sustainability. Not regulation-specific.
B8: Scoring | C8: Every answer-to-risk-level mapping. The lookup engine every tab reads.
B9: Questions | C9: The question bank in readable form.
B10: Legacy | C10: The superseded pre-2022 client-side test, for reference.
B12: What differs between the five
B13: CySEC v24 | C13: CySEC-24. Component 9 in Factor B. Scores 7 of the 8 answers the funnel offers for Q8. Hard block needs all 4 of Q9, Q8, Q10, Q11 to be in range. Check DefaultResult: NotBlocked.
B14: FCA v15 | C14: FCA-15. Component 9 not used. Scores 4 of the 8 answers the funnel offers for Q8. Hard block needs all 4 of Q9, Q8, Q10, Q11 to be in range. Check DefaultResult: Blocked.
B15: ASIC v9 | C15: ASIC-9. Component 9 not used. Scores 4 of the 8 answers the funnel offers for Q8. Hard block needs all 4 of Q9, Q8, Q10, Q11 to be in range. Check DefaultResult: not set.
B16: ASIC GAML v15 | C16: ASICGAML-15. Component 9 not used. Scores 4 of the 8 answers the funnel offers for Q8. Hard block needs all 5 of Q9, Q8, Q10, Q11, Q15 to be in range. Check DefaultResult: NotBlocked.
B17: FSRA v10 | C17: FSRA-10. Component 9 not used. Scores 4 of the 8 answers the funnel offers for Q8. Hard block needs all 4 of Q9, Q8, Q10, Q11 to be in range. Check DefaultResult: not set.
B19: On FCA | C19: FCA-15 is the only config that sets this check's DefaultResult to Blocked. It has no effect. Suitability calls BlockCalculator.Calculate, which hands the block-level DefaultResult (NotBlocked, same in all five configs) to every check and returns it when no check applies; Check.DefaultResult is only ever read for nested checks and this block has none. FCA therefore fails open on an unanswered question, exactly like the other four.
B21: The formula
C22: Factor A = MIN(Component 5, Component 6)
C23: Factor B = AVERAGE(Components 1, 2, 3, 4, 7, 8) rounded DOWN
C24: under CySEC, Component 9 joins that average
C25: ClientRiskLevel = MIN(Factor A, Factor B)
C26: Minimal|Low -> 3 Medium -> 6 MediumHigh -> 8 High -> 10
C27: A user may copy any trader or portfolio whose risk score is at or below that number.
B29: Level ordinals | C29: Minimal = 0, Low = 1, Medium = 2, MediumHigh = 3, High = 4. Unanswered components default to Medium.
B31: Read before relying on this
B32: Verified against the service | C32: Every formula, weight and band here is checked against the KYCAnalyzer source and the CySEC-24 configuration the service's own tests load. The 14 test vectors in WeightQuestionAnswerCalculatorTests all reproduce exactly.
B33: Component 9 is CySEC only | C33: The MiCA crypto block entered Factor B in CySEC-20. FCA, FSRA, ASIC and ASIC GAML average six components, not seven, so their Factor B row lists six. Use the tab that matches the user's regulation - the same answers give different outcomes across tabs.
B34: Gates this does not model | C34: Suitability is skipped below verification level 2, and eToro-country staff are forced to High when the feature flag is on. Crypto restrictions, professional-copy rules, MiCA documents and first-copy terms can also block a copy independently of suitability.
B35: Monitoring midpoints | C35: The band midpoints on the Monitoring sheet match the service's CCM answer-to-amount mapping, but the weightings x, y and z are read from CCM at runtime and could be retuned without a code change.
B37: Source | C37: rev-eng/suitability-test/ in the etoro-assets repository. Regenerate this file with build_workbook.py.

Sheet CySEC v24
A1: Suitability calculator - CySEC
A2: Answer the yellow cells; everything else is calculated. This sheet models CySEC-24, the live configuration for CySEC. Each regulation gets its own sheet because the scored answers and the hard block differ.
A4: STEP 1 - answer the questions
A5: Q | B5: Question | C5: Your answer | D5: Risk level | E5: Weight | F5: Feeds
A6: Q33 | B6: How often have you traded stocks? | C6: 0-10 times | D6: =IFERROR(VLOOKUP("Equities|"&C6,Scoring!$A$5:$E$89,4,FALSE),"?") | E6: =IFERROR(VLOOKUP("Equities|"&C6,Scoring!$A$5:$E$89,5,FALSE),"") | F6: Component 1
A7: Q34 | B7: How often have you traded crypto? | C7: Never traded | D7: =IFERROR(VLOOKUP("Crypto|"&C7,Scoring!$A$5:$E$89,4,FALSE),"?") | E7: =IFERROR(VLOOKUP("Crypto|"&C7,Scoring!$A$5:$E$89,5,FALSE),"") | F7: Component 1
A8: Q35 | B8: How often have you traded leveraged CFDs? | C8: Never traded | D8: =IFERROR(VLOOKUP("LeveragedCfd|"&C8,Scoring!$A$5:$E$89,4,FALSE),"?") | E8: =IFERROR(VLOOKUP("LeveragedCfd|"&C8,Scoring!$A$5:$E$89,5,FALSE),"") | F8: Component 1
A9: Q47 | B9: How much have you invested in stocks? | C9: $1 - $500 | D9: =IFERROR(VLOOKUP("EquitiesInvestedAmount|"&C9,Scoring!$A$5:$E$89,4,FALSE),"?") | E9: =IFERROR(VLOOKUP("EquitiesInvestedAmount|"&C9,Scoring!$A$5:$E$89,5,FALSE),"") | F9: Component 2
A10: Q48 | B10: How much have you invested in crypto? | C10: Never | D10: =IFERROR(VLOOKUP("CryptoInvestedAmount|"&C10,Scoring!$A$5:$E$89,4,FALSE),"?") | E10: =IFERROR(VLOOKUP("CryptoInvestedAmount|"&C10,Scoring!$A$5:$E$89,5,FALSE),"") | F10: Component 2
A11: Q45 | B11: How much have you invested in leveraged CFDs? | C11: Never | D11: =IFERROR(VLOOKUP("LeveragedCfdInvestedAmount|"&C11,Scoring!$A$5:$E$89,4,FALSE),"?") | E11: =IFERROR(VLOOKUP("LeveragedCfdInvestedAmount|"&C11,Scoring!$A$5:$E$89,5,FALSE),"") | F11: Component 2
A12: Q3 | B12: What relevant financial knowledge do you have? | C12: No financial knowledge | D12: =IFERROR(VLOOKUP("TradingKnowledge|"&C12,Scoring!$A$5:$E$89,4,FALSE),"?") | E12: =IFERROR(VLOOKUP("TradingKnowledge|"&C12,Scoring!$A$5:$E$89,5,FALSE),"") | F12: Component 3
A13: Q5 | B13: How long do you typically hold a position? | C13: A few weeks up to several months | D13: =IFERROR(VLOOKUP("TradingStrategy|"&C13,Scoring!$A$5:$E$89,4,FALSE),"?") | E13: =IFERROR(VLOOKUP("TradingStrategy|"&C13,Scoring!$A$5:$E$89,5,FALSE),"") | F13: Component 4
A14: Q8 | B14: What is your primary purpose for trading? | C14: Additional revenues | D14: =IF(OR(C14="Crypto trading and/or conversion"),"Medium (unscored - default)",IFERROR(VLOOKUP("TradingPurpose|"&C14,Scoring!$A$5:$E$89,4,FALSE),"?")) | E14: =IF(OR(C14="Crypto trading and/or conversion"),2,IFERROR(VLOOKUP("TradingPurpose|"&C14,Scoring!$A$5:$E$89,5,FALSE),"")) | F14: Component 5
A15: Q9 | B15: What gain and loss are you comfortable with? | C15: 20% / -12% | D15: =IFERROR(VLOOKUP("RiskAppetite|"&C15,Scoring!$A$5:$E$89,4,FALSE),"?") | E15: =IFERROR(VLOOKUP("RiskAppetite|"&C15,Scoring!$A$5:$E$89,5,FALSE),"") | F15: Component 6
A16: Q15 | B16: What is your main source of income? | C16: Salary | D16: =IFERROR(VLOOKUP("IncomeSource|"&C16,Scoring!$A$5:$E$89,4,FALSE),"?") | E16: =IFERROR(VLOOKUP("IncomeSource|"&C16,Scoring!$A$5:$E$89,5,FALSE),"") | F16: Component 7
A17: Q10 | B17: What is your net annual income? | C17: $50K - $200K | D17: not scored | E17: =IFERROR(VLOOKUP("AnnualIncome|"&C17,Scoring!$A$5:$E$89,5,FALSE),"") | F17: Hard block only
A18: Q11 | B18: What are your total cash and liquid assets? | C18: $50K - $200K | D18: not scored | E18: =IFERROR(VLOOKUP("LiquidAssets|"&C18,Scoring!$A$5:$E$89,5,FALSE),"") | F18: Hard block only
B20: CySEC-24 scores 7 of the 8 answers the funnel offers for Q8. The 1 it omits - Crypto trading and/or conversion - are still selectable in the funnel here, and each one silently takes the default risk level, Medium. Pick one and the risk-level cell says so.
A23: STEP 2 - Q23 complex-products knowledge assessment
B24: Six true/false statements shown as one multi-select. Mark Yes for each statement you would tick. Two are factually true and carry +2 - the analyzer enum annotates exactly those two as the correct answers - and four are false and carry -2.
B26: Every statement is judged, whether or not it is ticked. WeightQuestionAnswerCalculator.GetScoreByAnswerIds walks the whole group and does score += weight for a ticked answer, score -= weight for an unticked one, so ticking a true statement or leaving a false one alone both earn +2 and the opposite costs -2. The total runs -12 to +12 and no statement can contribute 0. The one exception: tick nothing and the group is skipped entirely, so component 8 falls back to the default risk level, Medium. Q23 is IsRequiredForCopy=false, so a user can leave it alone and still copy.
A29: ID | B29: Statement | C29: Selected? | D29: Weight | E29: Contribution | F29: Answer (config name)
A30: 142 | B30: I deposit and invest $1,000 to open a position with $20,000 (using leverage of 20x). If the market moves 5% against my position, I'll lose my investment | C30: Yes | D30: +2 | E30: =IF(C30="Yes",2,-2) | F30: NewerLeverage
A31: 144 | B31: If the total equity (i.e. the combined value of positions and available cash) in my account falls below the required margin, a "margin call" will liquidate my positions | C31: No | D31: +2 | E31: =IF(C31="Yes",2,-2) | F31: NewerMarginCall
A32: 143 | B32: If the price of Google's stock rises on NASDAQ, the price of my Google contract for difference (CFD) will go down | C32: Yes | D32: -2 | E32: =IF(C32="Yes",-2,2) | F32: NewerCfd
A33: 145 | B33: My open positions will remain open even when a stop loss is triggered | C33: No | D33: -2 | E33: =IF(C33="Yes",-2,2) | F33: NewerStopLossTrigger
A34: 146 | B34: If the market gaps through my stop loss, my position will close at the exact stop loss level | C34: No | D34: -2 | E34: =IF(C34="Yes",-2,2) | F34: NewerStopLossGapThrough
A35: 212 | B35: I will be able to sell my OTC complex products (CFD, TRS) outside of eToro platform [RETIRED - no longer asked] | C35: No | D35: -2 | E35: =IF(C35="Yes",-2,2) | F35: NewerCfdTrs
B36: Total assessment score | E36: =SUM(E30:E35) | F36: =IF(COUNTIF($C$30:$C$35,"Yes")=0,"nothing ticked - score not applied, component 8 falls back to Medium","reachable in production: -8 to +12")
B37: The last statement is scored by every live configuration but is no longer in the question catalogue, so no real user can tick it. It therefore contributes a constant +2 to everyone, which is why the reachable range is -8 to +12 rather than -12 to +12 and why High needs 4 of the 5 answerable statements rather than 5 of 6. It changes no band outcome - every threshold is 4 apart and the offset is 2. Leave it on No to model production; it stays editable only so the analyzer's own test vectors reproduce here.
B39: =IF(--(C35="Yes")>0,"Warning: a retired statement is ticked. No production user can do that - the score below is reachable only in the analyzer unit tests.","")
A41: STEP 3 - MiCA crypto knowledge (component 9)
B42: Component 9 entered Factor B in CySEC-20 and exists under no other regulation. Each question scores High for the one informed answer and Low for the two wrong ones; the five are averaged and rounded down. An unanswered question falls back to the component default, Low.
B44: Question | C44: Answer | D44: Risk level | E44: Weight | F44: Config name
B45: Crypto markets are highly volatile. This means: | C45: It can lead to significant gains or losses | D45: =IFERROR(VLOOKUP("MiCACryptoAssessmentHighVolatility|"&C45,Scoring!$A$5:$E$89,4,FALSE),"?") | E45: =IFERROR(VLOOKUP("MiCACryptoAssessmentHighVolatility|"&C45,Scoring!$A$5:$E$89,5,FALSE),1) | F45: MiCACryptoAssessmentHighVolatility
B46: Which of these best protects you from cyber risk? | C46: Enabling two-factor authentication | D46: =IFERROR(VLOOKUP("MiCACryptoAssessmentCyberRisks|"&C46,Scoring!$A$5:$E$89,4,FALSE),"?") | E46: =IFERROR(VLOOKUP("MiCACryptoAssessmentCyberRisks|"&C46,Scoring!$A$5:$E$89,5,FALSE),1) | F46: MiCACryptoAssessmentCyberRisks
B47: If you lose crypto assets, the law: | C47: Does not cover the loss | D47: =IFERROR(VLOOKUP("MiCACryptoAssessmentRecoverLoss|"&C47,Scoring!$A$5:$E$89,4,FALSE),"?") | E47: =IFERROR(VLOOKUP("MiCACryptoAssessmentRecoverLoss|"&C47,Scoring!$A$5:$E$89,5,FALSE),1) | F47: MiCACryptoAssessmentRecoverLoss
B48: The risk of investing in crypto is: | C48: You risk losing your whole investment | D48: =IFERROR(VLOOKUP("MiCACryptoAssessmentInvestingRisks|"&C48,Scoring!$A$5:$E$89,4,FALSE),"?") | E48: =IFERROR(VLOOKUP("MiCACryptoAssessmentInvestingRisks|"&C48,Scoring!$A$5:$E$89,5,FALSE),1) | F48: MiCACryptoAssessmentInvestingRisks
B49: A private key is: | C49: A secret code | D49: =IFERROR(VLOOKUP("MiCACryptoAssessmentPrivateKey|"&C49,Scoring!$A$5:$E$89,4,FALSE),"?") | E49: =IFERROR(VLOOKUP("MiCACryptoAssessmentPrivateKey|"&C49,Scoring!$A$5:$E$89,5,FALSE),1) | F49: MiCACryptoAssessmentPrivateKey
A51: STEP 4 - components
...

Sheet FCA v15
A1: Suitability calculator - FCA
A2: Answer the yellow cells; everything else is calculated. This sheet models FCA-15, the live configuration for FCA. Each regulation gets its own sheet because the scored answers and the hard block differ.
A4: STEP 1 - answer the questions
A5: Q | B5: Question | C5: Your answer | D5: Risk level | E5: Weight | F5: Feeds
A6: Q33 | B6: How often have you traded stocks? | C6: 0-10 times | D6: =IFERROR(VLOOKUP("Equities|"&C6,Scoring!$A$5:$E$89,4,FALSE),"?") | E6: =IFERROR(VLOOKUP("Equities|"&C6,Scoring!$A$5:$E$89,5,FALSE),"") | F6: Component 1
A7: Q34 | B7: How often have you traded crypto? | C7: Never traded | D7: =IFERROR(VLOOKUP("Crypto|"&C7,Scoring!$A$5:$E$89,4,FALSE),"?") | E7: =IFERROR(VLOOKUP("Crypto|"&C7,Scoring!$A$5:$E$89,5,FALSE),"") | F7: Component 1
A8: Q35 | B8: How often have you traded leveraged CFDs? | C8: Never traded | D8: =IFERROR(VLOOKUP("LeveragedCfd|"&C8,Scoring!$A$5:$E$89,4,FALSE),"?") | E8: =IFERROR(VLOOKUP("LeveragedCfd|"&C8,Scoring!$A$5:$E$89,5,FALSE),"") | F8: Component 1
A9: Q47 | B9: How much have you invested in stocks? | C9: $1 - $500 | D9: =IFERROR(VLOOKUP("EquitiesInvestedAmount|"&C9,Scoring!$A$5:$E$89,4,FALSE),"?") | E9: =IFERROR(VLOOKUP("EquitiesInvestedAmount|"&C9,Scoring!$A$5:$E$89,5,FALSE),"") | F9: Component 2
A10: Q48 | B10: How much have you invested in crypto? | C10: Never | D10: =IFERROR(VLOOKUP("CryptoInvestedAmount|"&C10,Scoring!$A$5:$E$89,4,FALSE),"?") | E10: =IFERROR(VLOOKUP("CryptoInvestedAmount|"&C10,Scoring!$A$5:$E$89,5,FALSE),"") | F10: Component 2
A11: Q45 | B11: How much have you invested in leveraged CFDs? | C11: Never | D11: =IFERROR(VLOOKUP("LeveragedCfdInvestedAmount|"&C11,Scoring!$A$5:$E$89,4,FALSE),"?") | E11: =IFERROR(VLOOKUP("LeveragedCfdInvestedAmount|"&C11,Scoring!$A$5:$E$89,5,FALSE),"") | F11: Component 2
A12: Q3 | B12: What relevant financial knowledge do you have? | C12: No financial knowledge | D12: =IFERROR(VLOOKUP("TradingKnowledge|"&C12,Scoring!$A$5:$E$89,4,FALSE),"?") | E12: =IFERROR(VLOOKUP("TradingKnowledge|"&C12,Scoring!$A$5:$E$89,5,FALSE),"") | F12: Component 3
A13: Q5 | B13: How long do you typically hold a position? | C13: A few weeks up to several months | D13: =IFERROR(VLOOKUP("TradingStrategy|"&C13,Scoring!$A$5:$E$89,4,FALSE),"?") | E13: =IFERROR(VLOOKUP("TradingStrategy|"&C13,Scoring!$A$5:$E$89,5,FALSE),"") | F13: Component 4
A14: Q8 | B14: What is your primary purpose for trading? | C14: Additional revenues | D14: =IF(OR(C14="Converting crypto to fiat",C14="Trading",C14="Investments",C14="Crypto trading and/or conversion"),"Medium (unscored - default)",IFERROR(VLOOKUP("TradingPurpose|"&C14,Scoring!$A$5:$E$89,4,FALSE),"?")) | E14: =IF(OR(C14="Converting crypto to fiat",C14="Trading",C14="Investments",C14="Crypto trading and/or conversion"),2,IFERROR(VLOOKUP("TradingPurpose|"&C14,Scoring!$A$5:$E$89,5,FALSE),"")) | F14: Component 5
A15: Q9 | B15: What gain and loss are you comfortable with? | C15: 20% / -12% | D15: =IFERROR(VLOOKUP("RiskAppetite|"&C15,Scoring!$A$5:$E$89,4,FALSE),"?") | E15: =IFERROR(VLOOKUP("RiskAppetite|"&C15,Scoring!$A$5:$E$89,5,FALSE),"") | F15: Component 6
A16: Q15 | B16: What is your main source of income? | C16: Salary | D16: =IFERROR(VLOOKUP("IncomeSource|"&C16,Scoring!$A$5:$E$89,4,FALSE),"?") | E16: =IFERROR(VLOOKUP("IncomeSource|"&C16,Scoring!$A$5:$E$89,5,FALSE),"") | F16: Component 7
A17: Q10 | B17: What is your net annual income? | C17: $50K - $200K | D17: not scored | E17: =IFERROR(VLOOKUP("AnnualIncome|"&C17,Scoring!$A$5:$E$89,5,FALSE),"") | F17: Hard block only
A18: Q11 | B18: What are your total cash and liquid assets? | C18: $50K - $200K | D18: not scored | E18: =IFERROR(VLOOKUP("LiquidAssets|"&C18,Scoring!$A$5:$E$89,5,FALSE),"") | F18: Hard block only
B20: FCA-15 scores 4 of the 8 answers the funnel offers for Q8. The 4 it omits - Converting crypto to fiat; Trading; Investments; Crypto trading and/or conversion - are still selectable in the funnel here, and each one silently takes the default risk level, Medium. Pick one and the risk-level cell says so.
A23: STEP 2 - Q23 complex-products knowledge assessment
B24: Six true/false statements shown as one multi-select. Mark Yes for each statement you would tick. Two are factually true and carry +2 - the analyzer enum annotates exactly those two as the correct answers - and four are false and carry -2.
B26: Every statement is judged, whether or not it is ticked. WeightQuestionAnswerCalculator.GetScoreByAnswerIds walks the whole group and does score += weight for a ticked answer, score -= weight for an unticked one, so ticking a true statement or leaving a false one alone both earn +2 and the opposite costs -2. The total runs -12 to +12 and no statement can contribute 0. The one exception: tick nothing and the group is skipped entirely, so component 8 falls back to the default risk level, Medium. Q23 is IsRequiredForCopy=false, so a user can leave it alone and still copy.
A29: ID | B29: Statement | C29: Selected? | D29: Weight | E29: Contribution | F29: Answer (config name)
A30: 142 | B30: I deposit and invest $1,000 to open a position with $20,000 (using leverage of 20x). If the market moves 5% against my position, I'll lose my investment | C30: Yes | D30: +2 | E30: =IF(C30="Yes",2,-2) | F30: NewerLeverage
A31: 144 | B31: If the total equity (i.e. the combined value of positions and available cash) in my account falls below the required margin, a "margin call" will liquidate my positions | C31: No | D31: +2 | E31: =IF(C31="Yes",2,-2) | F31: NewerMarginCall
A32: 143 | B32: If the price of Google's stock rises on NASDAQ, the price of my Google contract for difference (CFD) will go down | C32: Yes | D32: -2 | E32: =IF(C32="Yes",-2,2) | F32: NewerCfd
A33: 145 | B33: My open positions will remain open even when a stop loss is triggered | C33: No | D33: -2 | E33: =IF(C33="Yes",-2,2) | F33: NewerStopLossTrigger
A34: 146 | B34: If the market gaps through my stop loss, my position will close at the exact stop loss level | C34: No | D34: -2 | E34: =IF(C34="Yes",-2,2) | F34: NewerStopLossGapThrough
A35: 212 | B35: I will be able to sell my OTC complex products (CFD, TRS) outside of eToro platform [RETIRED - no longer asked] | C35: No | D35: -2 | E35: =IF(C35="Yes",-2,2) | F35: NewerCfdTrs
B36: Total assessment score | E36: =SUM(E30:E35) | F36: =IF(COUNTIF($C$30:$C$35,"Yes")=0,"nothing ticked - score not applied, component 8 falls back to Medium","reachable in production: -8 to +12")
B37: The last statement is scored by every live configuration but is no longer in the question catalogue, so no real user can tick it. It therefore contributes a constant +2 to everyone, which is why the reachable range is -8 to +12 rather than -12 to +12 and why High needs 4 of the 5 answerable statements rather than 5 of 6. It changes no band outcome - every threshold is 4 apart and the offset is 2. Leave it on No to model production; it stays editable only so the analyzer's own test vectors reproduce here.
B39: =IF(--(C35="Yes")>0,"Warning: a retired statement is ticked. No production user can do that - the score below is reachable only in the analyzer unit tests.","")
A41: STEP 3 - components
B42: Component | C42: Rule | D42: Risk level | E42: Weight | F42: Factor
B43: Component 1 - experience frequency | C43: MAX(stocks, crypto, CFD) | D43: =IFERROR(VLOOKUP(E43,Scoring!$A$94:$C$98,2,FALSE),"") | E43: =MAX(E6,E7,E8) | F43: Factor B
B44: Component 2 - experience volume | C44: MAX(stocks, crypto, CFD) | D44: =IFERROR(VLOOKUP(E44,Scoring!$A$94:$C$98,2,FALSE),"") | E44: =MAX(E9,E10,E11) | F44: Factor B
B45: Component 3 - trading knowledge | C45: single question | D45: =IFERROR(VLOOKUP(E45,Scoring!$A$94:$C$98,2,FALSE),"") | E45: =E12 | F45: Factor B
B46: Component 4 - trading strategy | C46: single question | D46: =IFERROR(VLOOKUP(E46,Scoring!$A$94:$C$98,2,FALSE),"") | E46: =E13 | F46: Factor B
B47: Component 5 - purpose of trading | C47: single question | D47: =IFERROR(VLOOKUP(E47,Scoring!$A$94:$C$98,2,FALSE),"") | E47: =E14 | F47: Factor A
B48: Component 6 - risk appetite | C48: single question | D48: =IFERROR(VLOOKUP(E48,Scoring!$A$94:$C$98,2,FALSE),"") | E48: =E15 | F48: Factor A
B49: Component 7 - source of income | C49: single question | D49: =IFERROR(VLOOKUP(E49,Scoring!$A$94:$C$98,2,FALSE),"") | E49: =E16 | F49: Factor B
...

Sheet ASIC v9
A1: Suitability calculator - ASIC
A2: Answer the yellow cells; everything else is calculated. This sheet models ASIC-9, the live configuration for ASIC. Each regulation gets its own sheet because the scored answers and the hard block differ.
A4: STEP 1 - answer the questions
A5: Q | B5: Question | C5: Your answer | D5: Risk level | E5: Weight | F5: Feeds
A6: Q33 | B6: How often have you traded stocks? | C6: 0-10 times | D6: =IFERROR(VLOOKUP("Equities|"&C6,Scoring!$A$5:$E$89,4,FALSE),"?") | E6: =IFERROR(VLOOKUP("Equities|"&C6,Scoring!$A$5:$E$89,5,FALSE),"") | F6: Component 1
A7: Q34 | B7: How often have you traded crypto? | C7: Never traded | D7: =IFERROR(VLOOKUP("Crypto|"&C7,Scoring!$A$5:$E$89,4,FALSE),"?") | E7: =IFERROR(VLOOKUP("Crypto|"&C7,Scoring!$A$5:$E$89,5,FALSE),"") | F7: Component 1
A8: Q35 | B8: How often have you traded leveraged CFDs? | C8: Never traded | D8: =IFERROR(VLOOKUP("LeveragedCfd|"&C8,Scoring!$A$5:$E$89,4,FALSE),"?") | E8: =IFERROR(VLOOKUP("LeveragedCfd|"&C8,Scoring!$A$5:$E$89,5,FALSE),"") | F8: Component 1
A9: Q47 | B9: How much have you invested in stocks? | C9: $1 - $500 | D9: =IFERROR(VLOOKUP("EquitiesInvestedAmount|"&C9,Scoring!$A$5:$E$89,4,FALSE),"?") | E9: =IFERROR(VLOOKUP("EquitiesInvestedAmount|"&C9,Scoring!$A$5:$E$89,5,FALSE),"") | F9: Component 2
A10: Q48 | B10: How much have you invested in crypto? | C10: Never | D10: =IFERROR(VLOOKUP("CryptoInvestedAmount|"&C10,Scoring!$A$5:$E$89,4,FALSE),"?") | E10: =IFERROR(VLOOKUP("CryptoInvestedAmount|"&C10,Scoring!$A$5:$E$89,5,FALSE),"") | F10: Component 2
A11: Q45 | B11: How much have you invested in leveraged CFDs? | C11: Never | D11: =IFERROR(VLOOKUP("LeveragedCfdInvestedAmount|"&C11,Scoring!$A$5:$E$89,4,FALSE),"?") | E11: =IFERROR(VLOOKUP("LeveragedCfdInvestedAmount|"&C11,Scoring!$A$5:$E$89,5,FALSE),"") | F11: Component 2
A12: Q3 | B12: What relevant financial knowledge do you have? | C12: No financial knowledge | D12: =IFERROR(VLOOKUP("TradingKnowledge|"&C12,Scoring!$A$5:$E$89,4,FALSE),"?") | E12: =IFERROR(VLOOKUP("TradingKnowledge|"&C12,Scoring!$A$5:$E$89,5,FALSE),"") | F12: Component 3
A13: Q5 | B13: How long do you typically hold a position? | C13: A few weeks up to several months | D13: =IFERROR(VLOOKUP("TradingStrategy|"&C13,Scoring!$A$5:$E$89,4,FALSE),"?") | E13: =IFERROR(VLOOKUP("TradingStrategy|"&C13,Scoring!$A$5:$E$89,5,FALSE),"") | F13: Component 4
A14: Q8 | B14: What is your primary purpose for trading? | C14: Additional revenues | D14: =IF(OR(C14="Converting crypto to fiat",C14="Trading",C14="Investments",C14="Crypto trading and/or conversion"),"Medium (unscored - default)",IFERROR(VLOOKUP("TradingPurpose|"&C14,Scoring!$A$5:$E$89,4,FALSE),"?")) | E14: =IF(OR(C14="Converting crypto to fiat",C14="Trading",C14="Investments",C14="Crypto trading and/or conversion"),2,IFERROR(VLOOKUP("TradingPurpose|"&C14,Scoring!$A$5:$E$89,5,FALSE),"")) | F14: Component 5
A15: Q9 | B15: What gain and loss are you comfortable with? | C15: 20% / -12% | D15: =IFERROR(VLOOKUP("RiskAppetite|"&C15,Scoring!$A$5:$E$89,4,FALSE),"?") | E15: =IFERROR(VLOOKUP("RiskAppetite|"&C15,Scoring!$A$5:$E$89,5,FALSE),"") | F15: Component 6
A16: Q15 | B16: What is your main source of income? | C16: Salary | D16: =IFERROR(VLOOKUP("IncomeSource|"&C16,Scoring!$A$5:$E$89,4,FALSE),"?") | E16: =IFERROR(VLOOKUP("IncomeSource|"&C16,Scoring!$A$5:$E$89,5,FALSE),"") | F16: Component 7
A17: Q10 | B17: What is your net annual income? | C17: $50K - $200K | D17: not scored | E17: =IFERROR(VLOOKUP("AnnualIncome|"&C17,Scoring!$A$5:$E$89,5,FALSE),"") | F17: Hard block only
A18: Q11 | B18: What are your total cash and liquid assets? | C18: $50K - $200K | D18: not scored | E18: =IFERROR(VLOOKUP("LiquidAssets|"&C18,Scoring!$A$5:$E$89,5,FALSE),"") | F18: Hard block only
B20: ASIC-9 scores 4 of the 8 answers the funnel offers for Q8. The 4 it omits - Converting crypto to fiat; Trading; Investments; Crypto trading and/or conversion - are still selectable in the funnel here, and each one silently takes the default risk level, Medium. Pick one and the risk-level cell says so.
A23: STEP 2 - Q23 complex-products knowledge assessment
B24: Six true/false statements shown as one multi-select. Mark Yes for each statement you would tick. Two are factually true and carry +2 - the analyzer enum annotates exactly those two as the correct answers - and four are false and carry -2.
B26: Every statement is judged, whether or not it is ticked. WeightQuestionAnswerCalculator.GetScoreByAnswerIds walks the whole group and does score += weight for a ticked answer, score -= weight for an unticked one, so ticking a true statement or leaving a false one alone both earn +2 and the opposite costs -2. The total runs -12 to +12 and no statement can contribute 0. The one exception: tick nothing and the group is skipped entirely, so component 8 falls back to the default risk level, Medium. Q23 is IsRequiredForCopy=false, so a user can leave it alone and still copy.
A29: ID | B29: Statement | C29: Selected? | D29: Weight | E29: Contribution | F29: Answer (config name)
A30: 142 | B30: I deposit and invest $1,000 to open a position with $20,000 (using leverage of 20x). If the market moves 5% against my position, I'll lose my investment | C30: Yes | D30: +2 | E30: =IF(C30="Yes",2,-2) | F30: NewerLeverage
A31: 144 | B31: If the total equity (i.e. the combined value of positions and available cash) in my account falls below the required margin, a "margin call" will liquidate my positions | C31: No | D31: +2 | E31: =IF(C31="Yes",2,-2) | F31: NewerMarginCall
A32: 143 | B32: If the price of Google's stock rises on NASDAQ, the price of my Google contract for difference (CFD) will go down | C32: Yes | D32: -2 | E32: =IF(C32="Yes",-2,2) | F32: NewerCfd
A33: 145 | B33: My open positions will remain open even when a stop loss is triggered | C33: No | D33: -2 | E33: =IF(C33="Yes",-2,2) | F33: NewerStopLossTrigger
A34: 146 | B34: If the market gaps through my stop loss, my position will close at the exact stop loss level | C34: No | D34: -2 | E34: =IF(C34="Yes",-2,2) | F34: NewerStopLossGapThrough
A35: 212 | B35: I will be able to sell my OTC complex products (CFD, TRS) outside of eToro platform [RETIRED - no longer asked] | C35: No | D35: -2 | E35: =IF(C35="Yes",-2,2) | F35: NewerCfdTrs
B36: Total assessment score | E36: =SUM(E30:E35) | F36: =IF(COUNTIF($C$30:$C$35,"Yes")=0,"nothing ticked - score not applied, component 8 falls back to Medium","reachable in production: -8 to +12")
B37: The last statement is scored by every live configuration but is no longer in the question catalogue, so no real user can tick it. It therefore contributes a constant +2 to everyone, which is why the reachable range is -8 to +12 rather than -12 to +12 and why High needs 4 of the 5 answerable statements rather than 5 of 6. It changes no band outcome - every threshold is 4 apart and the offset is 2. Leave it on No to model production; it stays editable only so the analyzer's own test vectors reproduce here.
B39: =IF(--(C35="Yes")>0,"Warning: a retired statement is ticked. No production user can do that - the score below is reachable only in the analyzer unit tests.","")
A41: STEP 3 - components
B42: Component | C42: Rule | D42: Risk level | E42: Weight | F42: Factor
B43: Component 1 - experience frequency | C43: MAX(stocks, crypto, CFD) | D43: =IFERROR(VLOOKUP(E43,Scoring!$A$94:$C$98,2,FALSE),"") | E43: =MAX(E6,E7,E8) | F43: Factor B
B44: Component 2 - experience volume | C44: MAX(stocks, crypto, CFD) | D44: =IFERROR(VLOOKUP(E44,Scoring!$A$94:$C$98,2,FALSE),"") | E44: =MAX(E9,E10,E11) | F44: Factor B
B45: Component 3 - trading knowledge | C45: single question | D45: =IFERROR(VLOOKUP(E45,Scoring!$A$94:$C$98,2,FALSE),"") | E45: =E12 | F45: Factor B
B46: Component 4 - trading strategy | C46: single question | D46: =IFERROR(VLOOKUP(E46,Scoring!$A$94:$C$98,2,FALSE),"") | E46: =E13 | F46: Factor B
B47: Component 5 - purpose of trading | C47: single question | D47: =IFERROR(VLOOKUP(E47,Scoring!$A$94:$C$98,2,FALSE),"") | E47: =E14 | F47: Factor A
B48: Component 6 - risk appetite | C48: single question | D48: =IFERROR(VLOOKUP(E48,Scoring!$A$94:$C$98,2,FALSE),"") | E48: =E15 | F48: Factor A
B49: Component 7 - source of income | C49: single question | D49: =IFERROR(VLOOKUP(E49,Scoring!$A$94:$C$98,2,FALSE),"") | E49: =E16 | F49: Factor B
...

Sheet ASIC GAML v15
A1: Suitability calculator - ASIC GAML
A2: Answer the yellow cells; everything else is calculated. This sheet models ASICGAML-15, the live configuration for ASIC GAML. Each regulation gets its own sheet because the scored answers and the hard block differ.
A4: STEP 1 - answer the questions
A5: Q | B5: Question | C5: Your answer | D5: Risk level | E5: Weight | F5: Feeds
A6: Q33 | B6: How often have you traded stocks? | C6: 0-10 times | D6: =IFERROR(VLOOKUP("Equities|"&C6,Scoring!$A$5:$E$89,4,FALSE),"?") | E6: =IFERROR(VLOOKUP("Equities|"&C6,Scoring!$A$5:$E$89,5,FALSE),"") | F6: Component 1
A7: Q34 | B7: How often have you traded crypto? | C7: Never traded | D7: =IFERROR(VLOOKUP("Crypto|"&C7,Scoring!$A$5:$E$89,4,FALSE),"?") | E7: =IFERROR(VLOOKUP("Crypto|"&C7,Scoring!$A$5:$E$89,5,FALSE),"") | F7: Component 1
A8: Q35 | B8: How often have you traded leveraged CFDs? | C8: Never traded | D8: =IFERROR(VLOOKUP("LeveragedCfd|"&C8,Scoring!$A$5:$E$89,4,FALSE),"?") | E8: =IFERROR(VLOOKUP("LeveragedCfd|"&C8,Scoring!$A$5:$E$89,5,FALSE),"") | F8: Component 1
A9: Q47 | B9: How much have you invested in stocks? | C9: $1 - $500 | D9: =IFERROR(VLOOKUP("EquitiesInvestedAmount|"&C9,Scoring!$A$5:$E$89,4,FALSE),"?") | E9: =IFERROR(VLOOKUP("EquitiesInvestedAmount|"&C9,Scoring!$A$5:$E$89,5,FALSE),"") | F9: Component 2
A10: Q48 | B10: How much have you invested in crypto? | C10: Never | D10: =IFERROR(VLOOKUP("CryptoInvestedAmount|"&C10,Scoring!$A$5:$E$89,4,FALSE),"?") | E10: =IFERROR(VLOOKUP("CryptoInvestedAmount|"&C10,Scoring!$A$5:$E$89,5,FALSE),"") | F10: Component 2
A11: Q45 | B11: How much have you invested in leveraged CFDs? | C11: Never | D11: =IFERROR(VLOOKUP("LeveragedCfdInvestedAmount|"&C11,Scoring!$A$5:$E$89,4,FALSE),"?") | E11: =IFERROR(VLOOKUP("LeveragedCfdInvestedAmount|"&C11,Scoring!$A$5:$E$89,5,FALSE),"") | F11: Component 2
A12: Q3 | B12: What relevant financial knowledge do you have? | C12: No financial knowledge | D12: =IFERROR(VLOOKUP("TradingKnowledge|"&C12,Scoring!$A$5:$E$89,4,FALSE),"?") | E12: =IFERROR(VLOOKUP("TradingKnowledge|"&C12,Scoring!$A$5:$E$89,5,FALSE),"") | F12: Component 3
A13: Q5 | B13: How long do you typically hold a position? | C13: A few weeks up to several months | D13: =IFERROR(VLOOKUP("TradingStrategy|"&C13,Scoring!$A$5:$E$89,4,FALSE),"?") | E13: =IFERROR(VLOOKUP("TradingStrategy|"&C13,Scoring!$A$5:$E$89,5,FALSE),"") | F13: Component 4
A14: Q8 | B14: What is your primary purpose for trading? | C14: Additional revenues | D14: =IF(OR(C14="Converting crypto to fiat",C14="Trading",C14="Investments",C14="Crypto trading and/or conversion"),"Medium (unscored - default)",IFERROR(VLOOKUP("TradingPurpose|"&C14,Scoring!$A$5:$E$89,4,FALSE),"?")) | E14: =IF(OR(C14="Converting crypto to fiat",C14="Trading",C14="Investments",C14="Crypto trading and/or conversion"),2,IFERROR(VLOOKUP("TradingPurpose|"&C14,Scoring!$A$5:$E$89,5,FALSE),"")) | F14: Component 5
A15: Q9 | B15: What gain and loss are you comfortable with? | C15: 20% / -12% | D15: =IFERROR(VLOOKUP("RiskAppetite|"&C15,Scoring!$A$5:$E$89,4,FALSE),"?") | E15: =IFERROR(VLOOKUP("RiskAppetite|"&C15,Scoring!$A$5:$E$89,5,FALSE),"") | F15: Component 6
A16: Q15 | B16: What is your main source of income? | C16: Salary | D16: =IFERROR(VLOOKUP("IncomeSource|"&C16,Scoring!$A$5:$E$89,4,FALSE),"?") | E16: =IFERROR(VLOOKUP("IncomeSource|"&C16,Scoring!$A$5:$E$89,5,FALSE),"") | F16: Component 7
A17: Q10 | B17: What is your net annual income? | C17: $50K - $200K | D17: not scored | E17: =IFERROR(VLOOKUP("AnnualIncome|"&C17,Scoring!$A$5:$E$89,5,FALSE),"") | F17: Hard block only
A18: Q11 | B18: What are your total cash and liquid assets? | C18: $50K - $200K | D18: not scored | E18: =IFERROR(VLOOKUP("LiquidAssets|"&C18,Scoring!$A$5:$E$89,5,FALSE),"") | F18: Hard block only
B20: ASICGAML-15 scores 4 of the 8 answers the funnel offers for Q8. The 4 it omits - Converting crypto to fiat; Trading; Investments; Crypto trading and/or conversion - are still selectable in the funnel here, and each one silently takes the default risk level, Medium. Pick one and the risk-level cell says so.
A23: STEP 2 - Q23 complex-products knowledge assessment
B24: Six true/false statements shown as one multi-select. Mark Yes for each statement you would tick. Two are factually true and carry +2 - the analyzer enum annotates exactly those two as the correct answers - and four are false and carry -2.
B26: Every statement is judged, whether or not it is ticked. WeightQuestionAnswerCalculator.GetScoreByAnswerIds walks the whole group and does score += weight for a ticked answer, score -= weight for an unticked one, so ticking a true statement or leaving a false one alone both earn +2 and the opposite costs -2. The total runs -12 to +12 and no statement can contribute 0. The one exception: tick nothing and the group is skipped entirely, so component 8 falls back to the default risk level, Medium. Q23 is IsRequiredForCopy=false, so a user can leave it alone and still copy.
A29: ID | B29: Statement | C29: Selected? | D29: Weight | E29: Contribution | F29: Answer (config name)
A30: 142 | B30: I deposit and invest $1,000 to open a position with $20,000 (using leverage of 20x). If the market moves 5% against my position, I'll lose my investment | C30: Yes | D30: +2 | E30: =IF(C30="Yes",2,-2) | F30: NewerLeverage
A31: 144 | B31: If the total equity (i.e. the combined value of positions and available cash) in my account falls below the required margin, a "margin call" will liquidate my positions | C31: No | D31: +2 | E31: =IF(C31="Yes",2,-2) | F31: NewerMarginCall
A32: 143 | B32: If the price of Google's stock rises on NASDAQ, the price of my Google contract for difference (CFD) will go down | C32: Yes | D32: -2 | E32: =IF(C32="Yes",-2,2) | F32: NewerCfd
A33: 145 | B33: My open positions will remain open even when a stop loss is triggered | C33: No | D33: -2 | E33: =IF(C33="Yes",-2,2) | F33: NewerStopLossTrigger
A34: 146 | B34: If the market gaps through my stop loss, my position will close at the exact stop loss level | C34: No | D34: -2 | E34: =IF(C34="Yes",-2,2) | F34: NewerStopLossGapThrough
A35: 212 | B35: I will be able to sell my OTC complex products (CFD, TRS) outside of eToro platform [RETIRED - no longer asked] | C35: No | D35: -2 | E35: =IF(C35="Yes",-2,2) | F35: NewerCfdTrs
B36: Total assessment score | E36: =SUM(E30:E35) | F36: =IF(COUNTIF($C$30:$C$35,"Yes")=0,"nothing ticked - score not applied, component 8 falls back to Medium","reachable in production: -8 to +12")
B37: The last statement is scored by every live configuration but is no longer in the question catalogue, so no real user can tick it. It therefore contributes a constant +2 to everyone, which is why the reachable range is -8 to +12 rather than -12 to +12 and why High needs 4 of the 5 answerable statements rather than 5 of 6. It changes no band outcome - every threshold is 4 apart and the offset is 2. Leave it on No to model production; it stays editable only so the analyzer's own test vectors reproduce here.
B39: =IF(--(C35="Yes")>0,"Warning: a retired statement is ticked. No production user can do that - the score below is reachable only in the analyzer unit tests.","")
A41: STEP 3 - components
B42: Component | C42: Rule | D42: Risk level | E42: Weight | F42: Factor
B43: Component 1 - experience frequency | C43: MAX(stocks, crypto, CFD) | D43: =IFERROR(VLOOKUP(E43,Scoring!$A$94:$C$98,2,FALSE),"") | E43: =MAX(E6,E7,E8) | F43: Factor B
B44: Component 2 - experience volume | C44: MAX(stocks, crypto, CFD) | D44: =IFERROR(VLOOKUP(E44,Scoring!$A$94:$C$98,2,FALSE),"") | E44: =MAX(E9,E10,E11) | F44: Factor B
B45: Component 3 - trading knowledge | C45: single question | D45: =IFERROR(VLOOKUP(E45,Scoring!$A$94:$C$98,2,FALSE),"") | E45: =E12 | F45: Factor B
B46: Component 4 - trading strategy | C46: single question | D46: =IFERROR(VLOOKUP(E46,Scoring!$A$94:$C$98,2,FALSE),"") | E46: =E13 | F46: Factor B
B47: Component 5 - purpose of trading | C47: single question | D47: =IFERROR(VLOOKUP(E47,Scoring!$A$94:$C$98,2,FALSE),"") | E47: =E14 | F47: Factor A
B48: Component 6 - risk appetite | C48: single question | D48: =IFERROR(VLOOKUP(E48,Scoring!$A$94:$C$98,2,FALSE),"") | E48: =E15 | F48: Factor A
B49: Component 7 - source of income | C49: single question | D49: =IFERROR(VLOOKUP(E49,Scoring!$A$94:$C$98,2,FALSE),"") | E49: =E16 | F49: Factor B
...

Sheet FSRA v10
A1: Suitability calculator - FSRA
A2: Answer the yellow cells; everything else is calculated. This sheet models FSRA-10, the live configuration for FSRA. Each regulation gets its own sheet because the scored answers and the hard block differ.
A4: STEP 1 - answer the questions
A5: Q | B5: Question | C5: Your answer | D5: Risk level | E5: Weight | F5: Feeds
A6: Q33 | B6: How often have you traded stocks? | C6: 0-10 times | D6: =IFERROR(VLOOKUP("Equities|"&C6,Scoring!$A$5:$E$89,4,FALSE),"?") | E6: =IFERROR(VLOOKUP("Equities|"&C6,Scoring!$A$5:$E$89,5,FALSE),"") | F6: Component 1
A7: Q34 | B7: How often have you traded crypto? | C7: Never traded | D7: =IFERROR(VLOOKUP("Crypto|"&C7,Scoring!$A$5:$E$89,4,FALSE),"?") | E7: =IFERROR(VLOOKUP("Crypto|"&C7,Scoring!$A$5:$E$89,5,FALSE),"") | F7: Component 1
A8: Q35 | B8: How often have you traded leveraged CFDs? | C8: Never traded | D8: =IFERROR(VLOOKUP("LeveragedCfd|"&C8,Scoring!$A$5:$E$89,4,FALSE),"?") | E8: =IFERROR(VLOOKUP("LeveragedCfd|"&C8,Scoring!$A$5:$E$89,5,FALSE),"") | F8: Component 1
A9: Q47 | B9: How much have you invested in stocks? | C9: $1 - $500 | D9: =IFERROR(VLOOKUP("EquitiesInvestedAmount|"&C9,Scoring!$A$5:$E$89,4,FALSE),"?") | E9: =IFERROR(VLOOKUP("EquitiesInvestedAmount|"&C9,Scoring!$A$5:$E$89,5,FALSE),"") | F9: Component 2
A10: Q48 | B10: How much have you invested in crypto? | C10: Never | D10: =IFERROR(VLOOKUP("CryptoInvestedAmount|"&C10,Scoring!$A$5:$E$89,4,FALSE),"?") | E10: =IFERROR(VLOOKUP("CryptoInvestedAmount|"&C10,Scoring!$A$5:$E$89,5,FALSE),"") | F10: Component 2
A11: Q45 | B11: How much have you invested in leveraged CFDs? | C11: Never | D11: =IFERROR(VLOOKUP("LeveragedCfdInvestedAmount|"&C11,Scoring!$A$5:$E$89,4,FALSE),"?") | E11: =IFERROR(VLOOKUP("LeveragedCfdInvestedAmount|"&C11,Scoring!$A$5:$E$89,5,FALSE),"") | F11: Component 2
A12: Q3 | B12: What relevant financial knowledge do you have? | C12: No financial knowledge | D12: =IFERROR(VLOOKUP("TradingKnowledge|"&C12,Scoring!$A$5:$E$89,4,FALSE),"?") | E12: =IFERROR(VLOOKUP("TradingKnowledge|"&C12,Scoring!$A$5:$E$89,5,FALSE),"") | F12: Component 3
A13: Q5 | B13: How long do you typically hold a position? | C13: A few weeks up to several months | D13: =IFERROR(VLOOKUP("TradingStrategy|"&C13,Scoring!$A$5:$E$89,4,FALSE),"?") | E13: =IFERROR(VLOOKUP("TradingStrategy|"&C13,Scoring!$A$5:$E$89,5,FALSE),"") | F13: Component 4
A14: Q8 | B14: What is your primary purpose for trading? | C14: Additional revenues | D14: =IF(OR(C14="Converting crypto to fiat",C14="Trading",C14="Investments",C14="Crypto trading and/or conversion"),"Medium (unscored - default)",IFERROR(VLOOKUP("TradingPurpose|"&C14,Scoring!$A$5:$E$89,4,FALSE),"?")) | E14: =IF(OR(C14="Converting crypto to fiat",C14="Trading",C14="Investments",C14="Crypto trading and/or conversion"),2,IFERROR(VLOOKUP("TradingPurpose|"&C14,Scoring!$A$5:$E$89,5,FALSE),"")) | F14: Component 5
A15: Q9 | B15: What gain and loss are you comfortable with? | C15: 20% / -12% | D15: =IFERROR(VLOOKUP("RiskAppetite|"&C15,Scoring!$A$5:$E$89,4,FALSE),"?") | E15: =IFERROR(VLOOKUP("RiskAppetite|"&C15,Scoring!$A$5:$E$89,5,FALSE),"") | F15: Component 6
A16: Q15 | B16: What is your main source of income? | C16: Salary | D16: =IFERROR(VLOOKUP("IncomeSource|"&C16,Scoring!$A$5:$E$89,4,FALSE),"?") | E16: =IFERROR(VLOOKUP("IncomeSource|"&C16,Scoring!$A$5:$E$89,5,FALSE),"") | F16: Component 7
A17: Q10 | B17: What is your net annual income? | C17: $50K - $200K | D17: not scored | E17: =IFERROR(VLOOKUP("AnnualIncome|"&C17,Scoring!$A$5:$E$89,5,FALSE),"") | F17: Hard block only
A18: Q11 | B18: What are your total cash and liquid assets? | C18: $50K - $200K | D18: not scored | E18: =IFERROR(VLOOKUP("LiquidAssets|"&C18,Scoring!$A$5:$E$89,5,FALSE),"") | F18: Hard block only
B20: FSRA-10 scores 4 of the 8 answers the funnel offers for Q8. The 4 it omits - Converting crypto to fiat; Trading; Investments; Crypto trading and/or conversion - are still selectable in the funnel here, and each one silently takes the default risk level, Medium. Pick one and the risk-level cell says so.
A23: STEP 2 - Q23 complex-products knowledge assessment
B24: Six true/false statements shown as one multi-select. Mark Yes for each statement you would tick. Two are factually true and carry +2 - the analyzer enum annotates exactly those two as the correct answers - and four are false and carry -2.
B26: Every statement is judged, whether or not it is ticked. WeightQuestionAnswerCalculator.GetScoreByAnswerIds walks the whole group and does score += weight for a ticked answer, score -= weight for an unticked one, so ticking a true statement or leaving a false one alone both earn +2 and the opposite costs -2. The total runs -12 to +12 and no statement can contribute 0. The one exception: tick nothing and the group is skipped entirely, so component 8 falls back to the default risk level, Medium. Q23 is IsRequiredForCopy=false, so a user can leave it alone and still copy.
A29: ID | B29: Statement | C29: Selected? | D29: Weight | E29: Contribution | F29: Answer (config name)
A30: 142 | B30: I deposit and invest $1,000 to open a position with $20,000 (using leverage of 20x). If the market moves 5% against my position, I'll lose my investment | C30: Yes | D30: +2 | E30: =IF(C30="Yes",2,-2) | F30: NewerLeverage
A31: 144 | B31: If the total equity (i.e. the combined value of positions and available cash) in my account falls below the required margin, a "margin call" will liquidate my positions | C31: No | D31: +2 | E31: =IF(C31="Yes",2,-2) | F31: NewerMarginCall
A32: 143 | B32: If the price of Google's stock rises on NASDAQ, the price of my Google contract for difference (CFD) will go down | C32: Yes | D32: -2 | E32: =IF(C32="Yes",-2,2) | F32: NewerCfd
A33: 145 | B33: My open positions will remain open even when a stop loss is triggered | C33: No | D33: -2 | E33: =IF(C33="Yes",-2,2) | F33: NewerStopLossTrigger
A34: 146 | B34: If the market gaps through my stop loss, my position will close at the exact stop loss level | C34: No | D34: -2 | E34: =IF(C34="Yes",-2,2) | F34: NewerStopLossGapThrough
A35: 212 | B35: I will be able to sell my OTC complex products (CFD, TRS) outside of eToro platform [RETIRED - no longer asked] | C35: No | D35: -2 | E35: =IF(C35="Yes",-2,2) | F35: NewerCfdTrs
B36: Total assessment score | E36: =SUM(E30:E35) | F36: =IF(COUNTIF($C$30:$C$35,"Yes")=0,"nothing ticked - score not applied, component 8 falls back to Medium","reachable in production: -8 to +12")
B37: The last statement is scored by every live configuration but is no longer in the question catalogue, so no real user can tick it. It therefore contributes a constant +2 to everyone, which is why the reachable range is -8 to +12 rather than -12 to +12 and why High needs 4 of the 5 answerable statements rather than 5 of 6. It changes no band outcome - every threshold is 4 apart and the offset is 2. Leave it on No to model production; it stays editable only so the analyzer's own test vectors reproduce here.
B39: =IF(--(C35="Yes")>0,"Warning: a retired statement is ticked. No production user can do that - the score below is reachable only in the analyzer unit tests.","")
A41: STEP 3 - components
B42: Component | C42: Rule | D42: Risk level | E42: Weight | F42: Factor
B43: Component 1 - experience frequency | C43: MAX(stocks, crypto, CFD) | D43: =IFERROR(VLOOKUP(E43,Scoring!$A$94:$C$98,2,FALSE),"") | E43: =MAX(E6,E7,E8) | F43: Factor B
B44: Component 2 - experience volume | C44: MAX(stocks, crypto, CFD) | D44: =IFERROR(VLOOKUP(E44,Scoring!$A$94:$C$98,2,FALSE),"") | E44: =MAX(E9,E10,E11) | F44: Factor B
B45: Component 3 - trading knowledge | C45: single question | D45: =IFERROR(VLOOKUP(E45,Scoring!$A$94:$C$98,2,FALSE),"") | E45: =E12 | F45: Factor B
B46: Component 4 - trading strategy | C46: single question | D46: =IFERROR(VLOOKUP(E46,Scoring!$A$94:$C$98,2,FALSE),"") | E46: =E13 | F46: Factor B
B47: Component 5 - purpose of trading | C47: single question | D47: =IFERROR(VLOOKUP(E47,Scoring!$A$94:$C$98,2,FALSE),"") | E47: =E14 | F47: Factor A
B48: Component 6 - risk appetite | C48: single question | D48: =IFERROR(VLOOKUP(E48,Scoring!$A$94:$C$98,2,FALSE),"") | E48: =E15 | F48: Factor A
B49: Component 7 - source of income | C49: single question | D49: =IFERROR(VLOOKUP(E49,Scoring!$A$94:$C$98,2,FALSE),"") | E49: =E16 | F49: Factor B
...

Sheet Monitoring
A1: Gate 3 - ongoing monitoring (daily solvency check)
A2: Blocks NEW copy positions only. Existing copies are never closed. Evaluated once per day, so changes take effect the following day.
B4: INPUTS
B5: Input | C5: Your answer | D5: Value used | E5: Notes
B6: Q10 - net annual income | C6: $10K - $50K | D6: =IFERROR(VLOOKUP(C6,Scoring!$A$125:$B$130,2,FALSE),0) | E6: band midpoint
B7: Q11 - total net worth / liquid assets | C7: $10K - $50K | D7: =IFERROR(VLOOKUP(C7,Scoring!$A$125:$B$130,2,FALSE),0) | E7: band midpoint
B8: Q14 - planned investment over the coming year | C8: $50K - $200K | D8: =IFERROR(VLOOKUP(C8,Scoring!$C$125:$D$130,2,FALSE),0) | E8: band midpoint; 'Above $1M' is open-ended
B9: Year of first-time deposit (FTD) | C9: 2021
B10: Current year | C10: 2026
B11: Years since FTD, including the FTD year | D11: =C10-C9+1
B12: Cash currently allocated to copies (CA) | C12: 40000 | E12: initial investments - cash removed + cash added
B13: Realised P/L on closed copies (RPL) | C13: 2000 | E13: closed mirror positions only
B15: CALCULATION
B16: Term | C16: Formula | D16: Value | E16: Notes
B17: FSUSTdeclared | C17: Q14 midpoint x 50% x years since FTD | D17: =D8*0.5*D11
B18: FSUSTcalculated | C18: (Q10 x 50%) + (Q11 x 50%) | D18: =D6*0.5+D7*0.5
B19: FSUST | C19: MIN(declared, calculated) | D19: =MIN(D17,D18)
B20: CU (copy utilisation) | C20: 50% x CA - RPL | D20: =0.5*C12-C13
B22: OUTCOME | C22: =IF(D20<=D19,"Allowed - copy utilisation is within financial sustainability","BLOCKED from opening new copies - utilisation exceeds sustainability")
B24: Caveat: the source documentation says 'Q1 answer' and 'average of Q3 answer' without defining which point in a band is used. This sheet uses band midpoints from the client code (answers.data.ts). A second midpoint table in basic-user.ts disagrees for the top band. Treat absolute values as indicative; the comparison logic is exact.

Sheet Scoring
A1: Scoring tables
A2: Verbatim from the live ClientRiskProfileConfiguration documents CySEC-24, FCA-15, ASIC-9, ASIC GAML-15 and FSRA-10. Every calculator tab looks up against column A.
A4: Lookup key | B4: Question | C4: Answer | D4: Risk level | E4: Weight | F4: Notes
A5: Equities|Never traded | B5: Q33 Equities | C5: Never traded | D5: Medium | E5: 2
A6: Equities|0-10 times | B6: Q33 Equities | C6: 0-10 times | D6: Medium | E6: 2
A7: Equities|10-20 times | B7: Q33 Equities | C7: 10-20 times | D7: MediumHigh | E7: 3
A8: Equities|Above 20 times | B8: Q33 Equities | C8: Above 20 times | D8: High | E8: 4
A9: Crypto|Never traded | B9: Q34 Crypto | C9: Never traded | D9: Medium | E9: 2
A10: Crypto|0-10 times | B10: Q34 Crypto | C10: 0-10 times | D10: MediumHigh | E10: 3
A11: Crypto|10-20 times | B11: Q34 Crypto | C11: 10-20 times | D11: High | E11: 4
A12: Crypto|Above 20 times | B12: Q34 Crypto | C12: Above 20 times | D12: High | E12: 4
A13: LeveragedCfd|Never traded | B13: Q35 LeveragedCfd | C13: Never traded | D13: Medium | E13: 2
A14: LeveragedCfd|0-10 times | B14: Q35 LeveragedCfd | C14: 0-10 times | D14: MediumHigh | E14: 3
A15: LeveragedCfd|10-20 times | B15: Q35 LeveragedCfd | C15: 10-20 times | D15: High | E15: 4
A16: LeveragedCfd|Above 20 times | B16: Q35 LeveragedCfd | C16: Above 20 times | D16: High | E16: 4
... A62: IncomeSource|Severance | B62: Q15 IncomeSource | C62: Severance | D62: Low | E62: 1
A63: AnnualIncome|Up to $10K | B63: Q10 AnnualIncome | C63: Up to $10K | D63: not scored | E63: 1 | F63: band rank; hard block needs rank <= 3
A64: AnnualIncome|$10K - $50K | B64: Q10 AnnualIncome | C64: $10K - $50K | D64: not scored | E64: 2 | F64: band rank; hard block needs rank <= 3
A65: AnnualIncome|$50K - $200K | B65: Q10 AnnualIncome | C65: $50K - $200K | D65: not scored | E65: 3 | F65: band rank; hard block needs rank <= 3
A66: AnnualIncome|$200K - $500K | B66: Q10 AnnualIncome | C66: $200K - $500K | D66: not scored | E66: 4 | F66: band rank; hard block needs rank <= 3
A67: AnnualIncome|$500K - $1M | B67: Q10 AnnualIncome | C67: $500K - $1M | D67: not scored | E67: 5 | F67: band rank; hard block needs rank <= 3
A68: AnnualIncome|$1M - $5M | B68: Q10 AnnualIncome | C68: $1M - $5M | D68: not scored | E68: 6 | F68: band rank; hard block needs rank <= 3
A69: LiquidAssets|Up to $10K | B69: Q11 LiquidAssets | C69: Up to $10K | D69: not scored | E69: 1 | F69: band rank; hard block needs rank <= 3
A70: LiquidAssets|$10K - $50K | B70: Q11 LiquidAssets | C70: $10K - $50K | D70: not scored | E70: 2 | F70: band rank; hard block needs rank <= 3
A71: LiquidAssets|$50K - $200K | B71: Q11 LiquidAssets | C71: $50K - $200K | D71: not scored | E71: 3 | F71: band rank; hard block needs rank <= 3
A72: LiquidAssets|$200K - $500K | B72: Q11 LiquidAssets | C72: $200K - $500K | D72: not scored | E72: 4 | F72: band rank; hard block needs rank <= 3
A73: LiquidAssets|$500K - $1M | B73: Q11 LiquidAssets | C73: $500K - $1M | D73: not scored | E73: 5 | F73: band rank; hard block needs rank <= 3
A74: LiquidAssets|$1M - $5M | B74: Q11 LiquidAssets | C74: $1M - $5M | D74: not scored | E74: 6 | F74: band rank; hard block needs rank <= 3
... A89: MiCACryptoAssessmentPrivateKey|A public identifier | B89: C9 MiCACryptoAssessmentPrivateKey | C89: A public identifier | D89: Low | E89: 1 | F89: CySEC only, from CySEC-20
A92: Risk level weight -> name and authorised risk score
A93: Weight | B93: Risk level | C93: AuthorizedRiskScore
A94: 0 | B94: Minimal | C94: 3
A95: 1 | B95: Low | C95: 3
A96: 2 | B96: Medium | C96: 6
A97: 3 | B97: MediumHigh | C97: 8
A98: 4 | B98: High | C98: 10
A101: Component 8 - knowledge assessment answer scores
A102: Six true/false statements presented as one multi-select. A positive weight marks a statement that is factually true.
A103: Answer (config name) | B103: Answer ID | C103: Weight | D103: Statement is | E103: Statement
A104: NewerLeverage | B104: 142 | C104: 2 | D104: TRUE | E104: I deposit and invest $1,000 to open a position with $20,000 (using leverage of 20x). If the market moves 5% against my position, I'll lose my investment
...

Sheet Questions
A1: Question bank
A2: Question and answer IDs are confirmed against the KycQuestion and KycAnswer enums in the KycAnalyzer contract package - the mapping the service itself compiles against.
A4: Q | B4: Config name | C4: Question | D4: Answer | E4: Risk level | F4: Weight
A5: Q33 | B5: Equities | C5: How often have you traded stocks? | D5: Never traded | E5: Medium | F5: 2
A6: Q33 | B6: Equities | C6: How often have you traded stocks? | D6: 0-10 times | E6: Medium | F6: 2
A7: Q33 | B7: Equities | C7: How often have you traded stocks? | D7: 10-20 times | E7: MediumHigh | F7: 3
A8: Q33 | B8: Equities | C8: How often have you traded stocks? | D8: Above 20 times | E8: High | F8: 4
A9: Q34 | B9: Crypto | C9: How often have you traded crypto? | D9: Never traded | E9: Medium | F9: 2
A10: Q34 | B10: Crypto | C10: How often have you traded crypto? | D10: 0-10 times | E10: MediumHigh | F10: 3
A11: Q34 | B11: Crypto | C11: How often have you traded crypto? | D11: 10-20 times | E11: High | F11: 4
A12: Q34 | B12: Crypto | C12: How often have you traded crypto? | D12: Above 20 times | E12: High | F12: 4
A13: Q35 | B13: LeveragedCfd | C13: How often have you traded leveraged CFDs? | D13: Never traded | E13: Medium | F13: 2
A14: Q35 | B14: LeveragedCfd | C14: How often have you traded leveraged CFDs? | D14: 0-10 times | E14: MediumHigh | F14: 3
A15: Q35 | B15: LeveragedCfd | C15: How often have you traded leveraged CFDs? | D15: 10-20 times | E15: High | F15: 4
A16: Q35 | B16: LeveragedCfd | C16: How often have you traded leveraged CFDs? | D16: Above 20 times | E16: High | F16: 4
... A62: Q15 | B62: IncomeSource | C62: What is your main source of income? | D62: Severance | E62: Low | F62: 1
A63: Q10 | B63: AnnualIncome | C63: What is your net annual income? | D63: Up to $10K | E63: hard block input
A64: Q10 | B64: AnnualIncome | C64: What is your net annual income? | D64: $10K - $50K | E64: hard block input
A65: Q10 | B65: AnnualIncome | C65: What is your net annual income? | D65: $50K - $200K | E65: hard block input
A66: Q10 | B66: AnnualIncome | C66: What is your net annual income? | D66: $200K - $500K | E66: hard block input
A67: Q10 | B67: AnnualIncome | C67: What is your net annual income? | D67: $500K - $1M | E67: hard block input
A68: Q10 | B68: AnnualIncome | C68: What is your net annual income? | D68: $1M - $5M | E68: hard block input
A69: Q11 | B69: LiquidAssets | C69: What are your total cash and liquid assets? | D69: Up to $10K | E69: hard block input
A70: Q11 | B70: LiquidAssets | C70: What are your total cash and liquid assets? | D70: $10K - $50K | E70: hard block input
A71: Q11 | B71: LiquidAssets | C71: What are your total cash and liquid assets? | D71: $50K - $200K | E71: hard block input
A72: Q11 | B72: LiquidAssets | C72: What are your total cash and liquid assets? | D72: $200K - $500K | E72: hard block input
A73: Q11 | B73: LiquidAssets | C73: What are your total cash and liquid assets? | D73: $500K - $1M | E73: hard block input
A74: Q11 | B74: LiquidAssets | C74: What are your total cash and liquid assets? | D74: $1M - $5M | E74: hard block input

Sheet Legacy
A1: Legacy client-side suitability test (pre-2022) - reference only
A2: Superseded but still shipped behind the NewSuitability2022 A/B flag. Produced a binary block, not a risk score. Documented so it is not mistaken for current behaviour.
A4: Sub-tests (true = failed)
A5: Appropriateness | B5: Server status | C5: FAILED=1, SUCCESS=2, BORDER_LINE=3, DEFAULT=0
A6: Objectives | B6: Client | C6: fail if: (CFD never traded AND holds > several months) OR purpose in {future planning, saving for home} OR risk appetite in {5%/-3%, 10%/-6%}
A7: Experience | B7: Client | C7: fail if ratio > 0.1 AND appropriateness failed
A8: the ratio | B8: Client | C8: (deposits - withdrawals) / (income midpoint + liquid-assets midpoint); window is deposits since FTD if FTD <= 365 days ago, otherwise the last 12 months
A9: Low tier | B9: Client | C9: income band <= $10K AND liquid assets band <= $10K
A11: Decision table
A12: Key (appropriateness, objectives, experience, tier) | B12: suitabilityTestValue | C12: Next screen | D12: Copy blocked?
A13: p,p,p,l / p,p,p,h | B13: 1 | C13: none | D13: no
A14: f,p,p,l / f,p,p,h | B14: 1 | C14: Risk Disclosure | D14: no
A15: f,p,f,h | B15: 2 | C15: Suitability Assessment - Experience (high) | D15: no
A16: f,f,p,h | B16: 3 | C16: Suitability Assessment - Experience (high) | D16: no
A17: f,f,f,h | B17: 2 | C17: Suitability Assessment - Experience (high) | D17: no
A18: f,p,f,l | B18: 2 | C18: Suitability Assessment - Experience (low) | D18: YES
A19: f,f,p,l | B19: 3 | C19: Suitability Assessment - Experience (low) | D19: YES
A20: f,f,f,l | B20: 2 | C20: Suitability Assessment - Experience (low) | D20: YES
A21: p,f,p,h | B21: 3 | C21: Suitability Assessment - Objectives (high) | D21: no
A22: p,f,p,l | B22: 3 | C22: Suitability Assessment - Objectives (low) | D22: YES
A24: The legacy test only ever blocked LOW-TIER users. A high-tier user who failed everything saw a warning screen and kept copy access. Six of the sixteen key combinations have no entry.

Sheet Lists
A1: Dropdown sources. Referenced by data validation on the input sheets.
A2: Equities | B2: Crypto | C2: LeveragedCfd | D2: EquitiesInvestedAmount | E2: CryptoInvestedAmount | F2: LeveragedCfdInvestedAmount | G2: TradingKnowledge | H2: TradingStrategy | I2: TradingPurpose | J2: RiskAppetite | K2: IncomeSource | L2: AnnualIncome | M2: LiquidAssets | N2: YesNo | O2: PlannedInvestment | P2: MiCACryptoAssessmentHighVolatility | Q2: MiCACryptoAssessmentCyberRisks | R2: MiCACryptoAssessmentRecoverLoss | S2: MiCACryptoAssessmentInvestingRisks | T2: MiCACryptoAssessmentPrivateKey
A3: Never traded | B3: Never traded | C3: Never traded | D3: Never | E3: Never | F3: Never | G3: Professional certificate / work experience | H3: A few seconds up to 24 hours | I3: Short-term returns | J3: 5% / -3% | K3: Salary | L3: Up to $10K | M3: Up to $10K | N3: Yes | O3: Up to $20K | P3: It can lead to significant gains or losses | Q3: Enabling two-factor authentication | R3: Does not cover the loss | S3: You risk losing your whole investment | T3: A secret code
A4: 0-10 times | B4: 0-10 times | C4: 0-10 times | D4: $1 - $500 | E4: $1 - $500 | F4: $1 - $500 | G4: University degree in finance | H4: A few weeks up to several months | I4: Additional revenues | J4: 10% / -6% | K4: Employment | L4: $10K - $50K | M4: $10K - $50K | N4: No | O4: $20K - $50K | P4: Crypto makes a stable investment | Q4: Using the same password everywhere | R4: Covers the recovery | S4: Minimal | T4: A shared password
A5: 10-20 times | B5: 10-20 times | C5: 10-20 times | D5: $500 - $2,000 | E5: $500 - $2,000 | F5: $500 - $2,000 | G5: Trading courses | H5: More than several months / years | I5: Future planning | J5: 20% / -12% | K5: Investments | L5: $50K - $200K | M5: $50K - $200K | O5: $50K - $200K | P5: Crypto guarantees long-term profits | Q5: Sharing private keys with friends | R5: Lets you claim from consumer services | S5: Low | T5: A public identifier
